[2020-06-10 13:46:05,041] {taskinstance.py:669} INFO - Dependencies all met for <TaskInstance: generator_v4.generate_file 2020-06-10T17:45:00+00:00 [queued]>
[2020-06-10 13:46:05,044] {taskinstance.py:669} INFO - Dependencies all met for <TaskInstance: generator_v4.generate_file 2020-06-10T17:45:00+00:00 [queued]>
[2020-06-10 13:46:05,048] {taskinstance.py:669} INFO - Dependencies all met for <TaskInstance: generator_v4.generate_file 2020-06-10T17:45:00+00:00 [queued]>
[2020-06-10 13:46:05,048] {taskinstance.py:879} INFO - 
--------------------------------------------------------------------------------
[2020-06-10 13:46:05,048] {taskinstance.py:880} INFO - Starting attempt 1 of 2
[2020-06-10 13:46:05,048] {taskinstance.py:881} INFO - 
--------------------------------------------------------------------------------
[2020-06-10 13:46:05,051] {taskinstance.py:669} INFO - Dependencies all met for <TaskInstance: generator_v4.generate_file 2020-06-10T17:45:00+00:00 [queued]>
[2020-06-10 13:46:05,052] {taskinstance.py:879} INFO - 
--------------------------------------------------------------------------------
[2020-06-10 13:46:05,052] {taskinstance.py:880} INFO - Starting attempt 1 of 2
[2020-06-10 13:46:05,052] {taskinstance.py:881} INFO - 
--------------------------------------------------------------------------------
[2020-06-10 13:46:05,291] {taskinstance.py:900} INFO - Executing <Task(PythonOperator): generate_file> on 2020-06-10T17:45:00+00:00
[2020-06-10 13:46:05,296] {standard_task_runner.py:53} INFO - Started process 14815 to run task
[2020-06-10 13:46:05,453] {logging_mixin.py:112} INFO - Running %s on host %s <TaskInstance: generator_v4.generate_file 2020-06-10T17:45:00+00:00 [running]> strx
[2020-06-10 13:46:05,462] {logging_mixin.py:112} INFO - Generating  1591811165 ...
[2020-06-10 13:46:05,462] {taskinstance.py:1145} ERROR - [Errno 2] No such file or directory: '../../cmpc_data/descortezador_1591811165.csv'
Traceback (most recent call last):
  File "/home/isaias/anaconda3/envs/cmpc/lib/python3.6/site-packages/airflow/models/taskinstance.py", line 983, in _run_raw_task
    result = task_copy.execute(context=context)
  File "/home/isaias/anaconda3/envs/cmpc/lib/python3.6/site-packages/airflow/operators/python_operator.py", line 113, in execute
    return_value = self.execute_callable()
  File "/home/isaias/anaconda3/envs/cmpc/lib/python3.6/site-packages/airflow/operators/python_operator.py", line 118, in execute_callable
    return self.python_callable(*self.op_args, **self.op_kwargs)
  File "/home/isaias/airflow/dags/generator.py", line 60, in generate_file
    with open(filepath , 'w') as f:
FileNotFoundError: [Errno 2] No such file or directory: '../../cmpc_data/descortezador_1591811165.csv'
[2020-06-10 13:46:05,463] {taskinstance.py:1168} INFO - Marking task as UP_FOR_RETRY
[2020-06-10 13:46:05,854] {taskinstance.py:900} INFO - Executing <Task(PythonOperator): generate_file> on 2020-06-10T17:45:00+00:00
[2020-06-10 13:46:05,856] {standard_task_runner.py:53} INFO - Started process 14816 to run task
[2020-06-10 13:46:06,014] {logging_mixin.py:112} INFO - Running %s on host %s <TaskInstance: generator_v4.generate_file 2020-06-10T17:45:00+00:00 [running]> strx
[2020-06-10 13:46:06,024] {logging_mixin.py:112} INFO - Generating  1591811166 ...
[2020-06-10 13:46:06,025] {taskinstance.py:1145} ERROR - [Errno 2] No such file or directory: '../../cmpc_data/descortezador_1591811166.csv'
Traceback (most recent call last):
  File "/home/isaias/anaconda3/envs/cmpc/lib/python3.6/site-packages/airflow/models/taskinstance.py", line 983, in _run_raw_task
    result = task_copy.execute(context=context)
  File "/home/isaias/anaconda3/envs/cmpc/lib/python3.6/site-packages/airflow/operators/python_operator.py", line 113, in execute
    return_value = self.execute_callable()
  File "/home/isaias/anaconda3/envs/cmpc/lib/python3.6/site-packages/airflow/operators/python_operator.py", line 118, in execute_callable
    return self.python_callable(*self.op_args, **self.op_kwargs)
  File "/home/isaias/airflow/dags/generator.py", line 60, in generate_file
    with open(filepath , 'w') as f:
FileNotFoundError: [Errno 2] No such file or directory: '../../cmpc_data/descortezador_1591811166.csv'
[2020-06-10 13:46:06,026] {taskinstance.py:1168} INFO - Marking task as UP_FOR_RETRY
[2020-06-10 13:46:14,513] {logging_mixin.py:112} INFO - [2020-06-10 13:46:14,512] {local_task_job.py:103} INFO - Task exited with return code 1
[2020-06-10 13:46:14,693] {logging_mixin.py:112} INFO - [2020-06-10 13:46:14,692] {local_task_job.py:103} INFO - Task exited with return code 1
