[2020-06-10 12:07:54,150] {taskinstance.py:669} INFO - Dependencies all met for <TaskInstance: generator_v2.generate_file 2020-06-10T00:11:00+00:00 [queued]>
[2020-06-10 12:07:54,161] {taskinstance.py:669} INFO - Dependencies all met for <TaskInstance: generator_v2.generate_file 2020-06-10T00:11:00+00:00 [queued]>
[2020-06-10 12:07:54,161] {taskinstance.py:879} INFO - 
--------------------------------------------------------------------------------
[2020-06-10 12:07:54,162] {taskinstance.py:880} INFO - Starting attempt 2 of 2
[2020-06-10 12:07:54,162] {taskinstance.py:881} INFO - 
--------------------------------------------------------------------------------
[2020-06-10 12:07:54,389] {taskinstance.py:900} INFO - Executing <Task(PythonOperator): generate_file> on 2020-06-10T00:11:00+00:00
[2020-06-10 12:07:54,393] {standard_task_runner.py:53} INFO - Started process 26542 to run task
[2020-06-10 12:07:54,567] {logging_mixin.py:112} INFO - Running %s on host %s <TaskInstance: generator_v2.generate_file 2020-06-10T00:11:00+00:00 [running]> strx
[2020-06-10 12:07:54,577] {logging_mixin.py:112} INFO - Generating  1591805274 ...
[2020-06-10 12:07:54,577] {taskinstance.py:1145} ERROR - [Errno 2] No such file or directory: '../../cmpc_data/descortezador_1591805274.csv'
Traceback (most recent call last):
  File "/home/isaias/anaconda3/envs/cmpc/lib/python3.6/site-packages/airflow/models/taskinstance.py", line 983, in _run_raw_task
    result = task_copy.execute(context=context)
  File "/home/isaias/anaconda3/envs/cmpc/lib/python3.6/site-packages/airflow/operators/python_operator.py", line 113, in execute
    return_value = self.execute_callable()
  File "/home/isaias/anaconda3/envs/cmpc/lib/python3.6/site-packages/airflow/operators/python_operator.py", line 118, in execute_callable
    return self.python_callable(*self.op_args, **self.op_kwargs)
  File "/home/isaias/airflow/dags/generator.py", line 60, in generate_file
    with open(filepath , 'w') as f:
FileNotFoundError: [Errno 2] No such file or directory: '../../cmpc_data/descortezador_1591805274.csv'
[2020-06-10 12:07:54,579] {taskinstance.py:1187} INFO - All retries failed; marking task as FAILED.dag_id=generator_v2, task_id=generate_file, execution_date=20200610T001100, start_date=20200610T160754, end_date=20200610T160754
[2020-06-10 12:08:03,982] {logging_mixin.py:112} INFO - [2020-06-10 12:08:03,981] {local_task_job.py:103} INFO - Task exited with return code 1
