[2020-06-10 11:13:44,085] {taskinstance.py:669} INFO - Dependencies all met for <TaskInstance: generator.generate_file 2017-01-24T00:11:00+00:00 [queued]>
[2020-06-10 11:13:44,100] {taskinstance.py:669} INFO - Dependencies all met for <TaskInstance: generator.generate_file 2017-01-24T00:11:00+00:00 [queued]>
[2020-06-10 11:13:44,101] {taskinstance.py:879} INFO - 
--------------------------------------------------------------------------------
[2020-06-10 11:13:44,101] {taskinstance.py:880} INFO - Starting attempt 2 of 2
[2020-06-10 11:13:44,101] {taskinstance.py:881} INFO - 
--------------------------------------------------------------------------------
[2020-06-10 11:13:44,259] {taskinstance.py:900} INFO - Executing <Task(PythonOperator): generate_file> on 2017-01-24T00:11:00+00:00
[2020-06-10 11:13:44,261] {standard_task_runner.py:53} INFO - Started process 19195 to run task
[2020-06-10 11:13:44,512] {logging_mixin.py:112} INFO - Running %s on host %s <TaskInstance: generator.generate_file 2017-01-24T00:11:00+00:00 [running]> strx
[2020-06-10 11:13:44,532] {logging_mixin.py:112} INFO - Generating  1591802024 ...
[2020-06-10 11:13:44,532] {taskinstance.py:1145} ERROR - [Errno 2] No such file or directory: '../../cmpc_data/descortezador_1591802024.csv'
Traceback (most recent call last):
  File "/home/isaias/anaconda3/envs/cmpc/lib/python3.6/site-packages/airflow/models/taskinstance.py", line 983, in _run_raw_task
    result = task_copy.execute(context=context)
  File "/home/isaias/anaconda3/envs/cmpc/lib/python3.6/site-packages/airflow/operators/python_operator.py", line 113, in execute
    return_value = self.execute_callable()
  File "/home/isaias/anaconda3/envs/cmpc/lib/python3.6/site-packages/airflow/operators/python_operator.py", line 118, in execute_callable
    return self.python_callable(*self.op_args, **self.op_kwargs)
  File "/home/isaias/airflow/dags/generator.py", line 60, in generate_file
    with open(filepath , 'w') as f:
FileNotFoundError: [Errno 2] No such file or directory: '../../cmpc_data/descortezador_1591802024.csv'
[2020-06-10 11:13:44,533] {taskinstance.py:1187} INFO - All retries failed; marking task as FAILED.dag_id=generator, task_id=generate_file, execution_date=20170124T001100, start_date=20200610T151344, end_date=20200610T151344
