[2020-06-18 15:13:43,359] {taskinstance.py:669} INFO - Dependencies all met for <TaskInstance: sh_preprensa_v1.sensor 2020-06-18T17:24:41.149604+00:00 [queued]>
[2020-06-18 15:13:44,015] {taskinstance.py:669} INFO - Dependencies all met for <TaskInstance: sh_preprensa_v1.sensor 2020-06-18T17:24:41.149604+00:00 [queued]>
[2020-06-18 15:13:44,015] {taskinstance.py:879} INFO - 
--------------------------------------------------------------------------------
[2020-06-18 15:13:44,015] {taskinstance.py:880} INFO - Starting attempt 3 of 4
[2020-06-18 15:13:44,015] {taskinstance.py:881} INFO - 
--------------------------------------------------------------------------------
[2020-06-18 15:13:44,757] {taskinstance.py:900} INFO - Executing <Task(PythonOperator): sensor> on 2020-06-18T17:24:41.149604+00:00
[2020-06-18 15:13:44,762] {standard_task_runner.py:53} INFO - Started process 3051 to run task
[2020-06-18 15:13:46,208] {logging_mixin.py:112} INFO - Running %s on host %s <TaskInstance: sh_preprensa_v1.sensor 2020-06-18T17:24:41.149604+00:00 [running]> strx
[2020-06-18 15:13:48,074] {logging_mixin.py:112} INFO - Sensoring...
[2020-06-18 15:16:15,993] {logging_mixin.py:112} INFO - [2020-06-18 15:16:15,992] {local_task_job.py:167} WARNING - State of this instance has been externally set to None. Taking the poison pill.
[2020-06-18 15:16:16,039] {helpers.py:325} INFO - Sending Signals.SIGTERM to GPID 3051
[2020-06-18 15:16:16,040] {taskinstance.py:954} ERROR - Received SIGTERM. Terminating subprocesses.
[2020-06-18 15:16:16,050] {taskinstance.py:1145} ERROR - Task received SIGTERM signal
Traceback (most recent call last):
  File "/home/isaias/anaconda3/envs/cmpc/lib/python3.6/site-packages/airflow/models/taskinstance.py", line 983, in _run_raw_task
    result = task_copy.execute(context=context)
  File "/home/isaias/anaconda3/envs/cmpc/lib/python3.6/site-packages/airflow/operators/python_operator.py", line 113, in execute
    return_value = self.execute_callable()
  File "/home/isaias/anaconda3/envs/cmpc/lib/python3.6/site-packages/airflow/operators/python_operator.py", line 118, in execute_callable
    return self.python_callable(*self.op_args, **self.op_kwargs)
  File "/home/isaias/airflow/dags/extract_SH_preprensa.py", line 112, in sensor
    sleep(5)
  File "/home/isaias/anaconda3/envs/cmpc/lib/python3.6/site-packages/airflow/models/taskinstance.py", line 956, in signal_handler
    raise AirflowException("Task received SIGTERM signal")
airflow.exceptions.AirflowException: Task received SIGTERM signal
[2020-06-18 15:16:16,051] {taskinstance.py:1187} INFO - All retries failed; marking task as FAILED.dag_id=sh_preprensa_v1, task_id=sensor, execution_date=20200618T172441, start_date=20200618T191343, end_date=20200618T191616
[2020-06-18 15:16:16,133] {helpers.py:291} INFO - Process psutil.Process(pid=3051, status='terminated') (3051) terminated with exit code 1
[2020-06-18 15:16:20,985] {logging_mixin.py:112} INFO - [2020-06-18 15:16:20,985] {local_task_job.py:103} INFO - Task exited with return code 1
