[2020-06-24 20:00:05,670] {taskinstance.py:669} INFO - Dependencies all met for <TaskInstance: integrator.integrate_files 2020-06-24T16:00:00+00:00 [queued]>
[2020-06-24 20:00:05,724] {taskinstance.py:669} INFO - Dependencies all met for <TaskInstance: integrator.integrate_files 2020-06-24T16:00:00+00:00 [queued]>
[2020-06-24 20:00:05,726] {taskinstance.py:879} INFO - 
--------------------------------------------------------------------------------
[2020-06-24 20:00:05,726] {taskinstance.py:880} INFO - Starting attempt 1 of 2
[2020-06-24 20:00:05,726] {taskinstance.py:881} INFO - 
--------------------------------------------------------------------------------
[2020-06-24 20:00:05,763] {taskinstance.py:900} INFO - Executing <Task(PythonOperator): integrate_files> on 2020-06-24T16:00:00+00:00
[2020-06-24 20:00:05,768] {standard_task_runner.py:53} INFO - Started process 14951 to run task
[2020-06-24 20:00:05,983] {logging_mixin.py:112} INFO - Running %s on host %s <TaskInstance: integrator.integrate_files 2020-06-24T16:00:00+00:00 [running]> strx
[2020-06-24 20:00:06,073] {logging_mixin.py:112} INFO - Database(MongoClient(host=['localhost:27017'], document_class=dict, tz_aware=False, connect=True), 'cmpc')
[2020-06-24 20:00:07,173] {taskinstance.py:1145} ERROR - name 'data' is not defined
Traceback (most recent call last):
  File "/home/isaias/anaconda3/envs/cmpc/lib/python3.6/site-packages/airflow/models/taskinstance.py", line 983, in _run_raw_task
    result = task_copy.execute(context=context)
  File "/home/isaias/anaconda3/envs/cmpc/lib/python3.6/site-packages/airflow/operators/python_operator.py", line 113, in execute
    return_value = self.execute_callable()
  File "/home/isaias/anaconda3/envs/cmpc/lib/python3.6/site-packages/airflow/operators/python_operator.py", line 118, in execute_callable
    return self.python_callable(*self.op_args, **self.op_kwargs)
  File "/home/isaias/airflow/dags/integrator.py", line 115, in integrate
    processed_files = get_processed_files()
  File "/home/isaias/airflow/dags/integrator.py", line 106, in get_processed_files
    return data
NameError: name 'data' is not defined
[2020-06-24 20:00:07,176] {taskinstance.py:1168} INFO - Marking task as UP_FOR_RETRY
[2020-06-24 20:00:15,617] {logging_mixin.py:112} INFO - [2020-06-24 20:00:15,616] {local_task_job.py:103} INFO - Task exited with return code 1
