[2020-06-24 20:05:14,496] {taskinstance.py:669} INFO - Dependencies all met for <TaskInstance: integrator.integrate_files 2020-06-24T16:00:00+00:00 [queued]>
[2020-06-24 20:05:14,526] {taskinstance.py:669} INFO - Dependencies all met for <TaskInstance: integrator.integrate_files 2020-06-24T16:00:00+00:00 [queued]>
[2020-06-24 20:05:14,527] {taskinstance.py:879} INFO - 
--------------------------------------------------------------------------------
[2020-06-24 20:05:14,527] {taskinstance.py:880} INFO - Starting attempt 2 of 2
[2020-06-24 20:05:14,527] {taskinstance.py:881} INFO - 
--------------------------------------------------------------------------------
[2020-06-24 20:05:14,546] {taskinstance.py:900} INFO - Executing <Task(PythonOperator): integrate_files> on 2020-06-24T16:00:00+00:00
[2020-06-24 20:05:14,548] {standard_task_runner.py:53} INFO - Started process 21317 to run task
[2020-06-24 20:05:14,627] {logging_mixin.py:112} INFO - Running %s on host %s <TaskInstance: integrator.integrate_files 2020-06-24T16:00:00+00:00 [running]> strx
[2020-06-24 20:05:14,654] {logging_mixin.py:112} INFO - Database(MongoClient(host=['localhost:27017'], document_class=dict, tz_aware=False, connect=True), 'cmpc')
[2020-06-24 20:05:15,098] {taskinstance.py:1145} ERROR - name 'data' is not defined
Traceback (most recent call last):
  File "/home/isaias/anaconda3/envs/cmpc/lib/python3.6/site-packages/airflow/models/taskinstance.py", line 983, in _run_raw_task
    result = task_copy.execute(context=context)
  File "/home/isaias/anaconda3/envs/cmpc/lib/python3.6/site-packages/airflow/operators/python_operator.py", line 113, in execute
    return_value = self.execute_callable()
  File "/home/isaias/anaconda3/envs/cmpc/lib/python3.6/site-packages/airflow/operators/python_operator.py", line 118, in execute_callable
    return self.python_callable(*self.op_args, **self.op_kwargs)
  File "/home/isaias/airflow/dags/integrator.py", line 115, in integrate
    processed_files = get_processed_files()
  File "/home/isaias/airflow/dags/integrator.py", line 106, in get_processed_files
    return data
NameError: name 'data' is not defined
[2020-06-24 20:05:15,100] {taskinstance.py:1187} INFO - All retries failed; marking task as FAILED.dag_id=integrator, task_id=integrate_files, execution_date=20200624T160000, start_date=20200625T000514, end_date=20200625T000515
[2020-06-24 20:05:24,458] {logging_mixin.py:112} INFO - [2020-06-24 20:05:24,457] {local_task_job.py:103} INFO - Task exited with return code 1
