[2020-06-18 21:12:39,825] {taskinstance.py:669} INFO - Dependencies all met for <TaskInstance: integrator.integrate_files 2020-06-18T16:00:00+00:00 [queued]>
[2020-06-18 21:12:39,871] {taskinstance.py:669} INFO - Dependencies all met for <TaskInstance: integrator.integrate_files 2020-06-18T16:00:00+00:00 [queued]>
[2020-06-18 21:12:39,872] {taskinstance.py:879} INFO - 
--------------------------------------------------------------------------------
[2020-06-18 21:12:39,872] {taskinstance.py:880} INFO - Starting attempt 2 of 2
[2020-06-18 21:12:39,872] {taskinstance.py:881} INFO - 
--------------------------------------------------------------------------------
[2020-06-18 21:12:39,945] {taskinstance.py:900} INFO - Executing <Task(PythonOperator): integrate_files> on 2020-06-18T16:00:00+00:00
[2020-06-18 21:12:39,952] {standard_task_runner.py:53} INFO - Started process 26228 to run task
[2020-06-18 21:12:40,087] {logging_mixin.py:112} INFO - Running %s on host %s <TaskInstance: integrator.integrate_files 2020-06-18T16:00:00+00:00 [running]> strx
[2020-06-18 21:12:40,116] {taskinstance.py:1145} ERROR - read_csv() missing 2 required positional arguments: 'include_names' and 'separator'
Traceback (most recent call last):
  File "/home/isaias/anaconda3/envs/cmpc/lib/python3.6/site-packages/airflow/models/taskinstance.py", line 983, in _run_raw_task
    result = task_copy.execute(context=context)
  File "/home/isaias/anaconda3/envs/cmpc/lib/python3.6/site-packages/airflow/operators/python_operator.py", line 113, in execute
    return_value = self.execute_callable()
  File "/home/isaias/anaconda3/envs/cmpc/lib/python3.6/site-packages/airflow/operators/python_operator.py", line 118, in execute_callable
    return self.python_callable(*self.op_args, **self.op_kwargs)
  File "/home/isaias/airflow/dags/integrator.py", line 95, in integrate
    data = read_csv(PROCESSED_FOLDER+"recepcion/Recepcion_634.csv")
TypeError: read_csv() missing 2 required positional arguments: 'include_names' and 'separator'
[2020-06-18 21:12:40,118] {taskinstance.py:1187} INFO - All retries failed; marking task as FAILED.dag_id=integrator, task_id=integrate_files, execution_date=20200618T160000, start_date=20200619T011239, end_date=20200619T011240
[2020-06-18 21:12:49,794] {logging_mixin.py:112} INFO - [2020-06-18 21:12:49,793] {local_task_job.py:103} INFO - Task exited with return code 1
[2020-06-18 21:46:24,432] {taskinstance.py:669} INFO - Dependencies all met for <TaskInstance: integrator.integrate_files 2020-06-18T16:00:00+00:00 [queued]>
[2020-06-18 21:46:24,462] {taskinstance.py:669} INFO - Dependencies all met for <TaskInstance: integrator.integrate_files 2020-06-18T16:00:00+00:00 [queued]>
[2020-06-18 21:46:24,462] {taskinstance.py:879} INFO - 
--------------------------------------------------------------------------------
[2020-06-18 21:46:24,462] {taskinstance.py:880} INFO - Starting attempt 2 of 2
[2020-06-18 21:46:24,462] {taskinstance.py:881} INFO - 
--------------------------------------------------------------------------------
[2020-06-18 21:46:24,484] {taskinstance.py:900} INFO - Executing <Task(PythonOperator): integrate_files> on 2020-06-18T16:00:00+00:00
[2020-06-18 21:46:24,487] {standard_task_runner.py:53} INFO - Started process 16286 to run task
[2020-06-18 21:46:24,564] {logging_mixin.py:112} INFO - Running %s on host %s <TaskInstance: integrator.integrate_files 2020-06-18T16:00:00+00:00 [running]> strx
[2020-06-18 21:46:24,590] {taskinstance.py:1145} ERROR - [Errno 2] No such file or directory: '/home/isaias/airflow/repository/processed_data/recepcion/Recepcion_634.csv'
Traceback (most recent call last):
  File "/home/isaias/anaconda3/envs/cmpc/lib/python3.6/site-packages/airflow/models/taskinstance.py", line 983, in _run_raw_task
    result = task_copy.execute(context=context)
  File "/home/isaias/anaconda3/envs/cmpc/lib/python3.6/site-packages/airflow/operators/python_operator.py", line 113, in execute
    return_value = self.execute_callable()
  File "/home/isaias/anaconda3/envs/cmpc/lib/python3.6/site-packages/airflow/operators/python_operator.py", line 118, in execute_callable
    return self.python_callable(*self.op_args, **self.op_kwargs)
  File "/home/isaias/airflow/dags/integrator.py", line 95, in integrate
    data = read_csv(PROCESSED_FOLDER+"recepcion/Recepcion_634.csv", include_names=1, separator=',')
  File "/home/isaias/airflow/dags/integrator.py", line 70, in read_csv
    with open(filepath, newline='') as f:
FileNotFoundError: [Errno 2] No such file or directory: '/home/isaias/airflow/repository/processed_data/recepcion/Recepcion_634.csv'
[2020-06-18 21:46:24,591] {taskinstance.py:1187} INFO - All retries failed; marking task as FAILED.dag_id=integrator, task_id=integrate_files, execution_date=20200618T160000, start_date=20200619T014624, end_date=20200619T014624
[2020-06-18 21:46:34,406] {logging_mixin.py:112} INFO - [2020-06-18 21:46:34,405] {local_task_job.py:103} INFO - Task exited with return code 1
